1 在方法中，如果抛出异常，且没有被捕获，则程序报错并中断执行

2 如果在方法外（声明方法处）通过throw提前抛出异常，则此方法中断执行，异常向上抛出，如果上层没有捕获此异常，则同（1）

3 如果上层方法通过try catch捕获了此异常，try中异常后面的逻辑不执行，try外层的程序继续执行,且执行catch中的逻辑，但是顺序无法保证                     


java中进行异常检查会非常影响性能，所以设计的时候要注意，只针对不正确的条件才使用异常，例子如下

```
// 对每一种情况进行异常检查（22ms）
private void call_1(List<Integer> list) {  
    long t = System.currentTimeMillis();  
    try {  
        int index = 0;  
        while(true) {  
            list.get(index++);  
        }   
    } catch (IndexOutOfBoundsException e) {  
        LogUtils.printTimeUsed("不针对检查异常", t);  
    }  
}

// 只对错误的情况进行异常检查（6ms）
private void call_2(List<Integer> list) {  
    long t = System.currentTimeMillis();  
    t = System.currentTimeMillis();  
    int size = list.size();  
    int index = 0;  
    while(true) {  
        if (index >= size) {  
            try {  
                list.get(index++);  
            } catch (IndexOutOfBoundsException e) {  
                LogUtils.printTimeUsed("针对性检查异常", t);  
                break;  
            }  
        }  
        list.get(index++);  
    }  
}  

// 普通的循环遍历(7ms)
private void call_3(List<Integer> list) {  
    long t = System.currentTimeMillis();  
    t = System.currentTimeMillis();  
    int size = list.size();  
    int index = 0;  
    for (index = 0; index < size; index++) {  
        list.get(index++);  
    }  

    LogUtils.printTimeUsed("循环遍历", t);  
}  

```

关于 finally：无论放生了什么，finally字句始终都会执行，即便是你在try或catch中加入了continue、break或者return

